# Chapter 09. Error Handling

Rust将错误分为两类，一类可以恢复的非致命错误，通过`Result<T, E>`来表示操作的结果，而一类不可恢复的致命错误，往往代表了程序存在逻辑性问题，例如数组越界访问，通过`panic!`宏立即终止程序运行

## 9.1 Unrecoverable Errors with `panic!`

当一个`panic`发生时，程序开始**栈展开unwinding**并清理所有资源（可以在`Cargo.toml`中的`[profile.release]`指定`panic = 'abort'`来跳过清理过程而在`panic`时直接退出程序）

```rust
fn main() {
    panic!("crash and burn");
}
```

```shell
$ cargo run
   Compiling panic v0.1.0 (file:///projects/panic)
    Finished dev [unoptimized + debuginfo] target(s) in 0.25s
     Running `target/debug/panic`
thread 'main' panicked at 'crash and burn', src/main.rs:2:5
note: run with `RUST_BACKTRACE=1` environment variable to display a backtrace
```

通过设置环境变量`RUST_BACKTRACE=1`可以使`panic!`时打印出调用栈：

```rust
fn main() {
    let v = vec![1, 2, 3];

    v[99];  // panic due to out-of-range
}
```

```shell
$ RUST_BACKTRACE=1 cargo run
thread 'main' panicked at 'index out of bounds: the len is 3 but the index is 99', src/main.rs:4:5
stack backtrace:
   0: rust_begin_unwind
             at /rustc/7eac88abb2e57e752f3302f02be5f3ce3d7adfb4/library/std/src/panicking.rs:483
   1: core::panicking::panic_fmt
             at /rustc/7eac88abb2e57e752f3302f02be5f3ce3d7adfb4/library/core/src/panicking.rs:85
   2: core::panicking::panic_bounds_check
             at /rustc/7eac88abb2e57e752f3302f02be5f3ce3d7adfb4/library/core/src/panicking.rs:62
   3: <usize as core::slice::index::SliceIndex<[T]>>::index
             at /rustc/7eac88abb2e57e752f3302f02be5f3ce3d7adfb4/library/core/src/slice/index.rs:255
   4: core::slice::index::<impl core::ops::index::Index<I> for [T]>::index
             at /rustc/7eac88abb2e57e752f3302f02be5f3ce3d7adfb4/library/core/src/slice/index.rs:15
   5: <alloc::vec::Vec<T> as core::ops::index::Index<I>>::index
             at /rustc/7eac88abb2e57e752f3302f02be5f3ce3d7adfb4/library/alloc/src/vec.rs:1982
   6: panic::main
             at ./src/main.rs:4
   7: core::ops::function::FnOnce::call_once
             at /rustc/7eac88abb2e57e752f3302f02be5f3ce3d7adfb4/library/core/src/ops/function.rs:227
note: Some details are omitted, run with `RUST_BACKTRACE=full` for a verbose backtrace.
```

注意：**打印调用栈必须存在`debug`符号信息**，在没有`--release`的情况下默认会有这些符号信息

## 9.2 Recoverable Errors with `Result`

- 采用`Result`可以包含预期的结果或错误情况，随后根据错误进行相应的处理：

    ```rust
    enum Result<T, E> {
        Ok(T),
        Err(E),
    }
    ```

    例如打开一个文件由于文件不存在而失败往往不是致命错误，可以在处理不存在错误时手动创建

    ```rust
    use std::fs::File;

    fn main() {
        let f = File::open("hello.txt");

        let f = match f {
            Ok(file) => file,
            Err(error) => panic!("Problem opening the file: {:?}", error),
        };
    }
    ```

- 对于不同类型的错误，同样可以采用`match`进行处理（其他还可以使用闭包和`.unwrap_or_else(closure)`等方式简化）：

    ```rust
    use std::fs::File;
    use std::io::ErrorKind;

    fn main() {
        let f = File::open("hello.txt");

        let f = match f {
            Ok(file) => file,
            Err(error) => match error.kind() {
                // try create file if not found
                ErrorKind::NotFound => match File::create("hello.txt") {
                    Ok(fc) => fc,
                    Err(e) => panic!("Problem creating the file: {:?}", e),
                },
                other_error => {
                    panic!("Problem opening the file: {:?}", other_error)
                }
            },
        };
    }
    ```

- 对于`Result`来说还存在非常多的辅助函数来简化各种错误的处理，例如：

    ```rust
    use std::fs::File;

    fn main() {
        // .unwrap()会直接在有Err的情况下调用panic!
        let f = File::open("hello.txt").unwrap();

        // .expect(msg)同样会在Err的情况下调用panic!，但会采用我们提供的信息
        let f = File::open("hello.txt").expect("Failed to open hello.txt");
    }
    ```

- 并不是每个遇到错误的函数都能立即处理相应的错误，有时候需要将错误向上传递至能够处理的位置，因此需要返回`Result`：

    ```rust
    use std::fs::File;
    use std::io::{self, Read};

    fn read_username_from_file() -> Result<String, io::Error> {
        let f = File::open("hello.txt");

        let mut f = match f {
            Ok(file) => file,
            Err(e) => return Err(e),
        };

        let mut s = String::new();

        match f.read_to_string(&mut s) {
            Ok(_) => Ok(s),
            Err(e) => Err(e),
        }
    }
    ```

    上述这种检查每个函数调用的返回值并`match`的范式极其常规和普遍，因此**Rust提供了额外的操作符`?`来代表有错误就提前返回**的操作，在`Result`后加上`?`就意味着遇到错误提前返回，并且**返回值类型必须兼容**：

    ```rust
    use std::fs::File;
    use std::io;
    use std::io::Read;

    fn read_username_from_file() -> Result<String, io::Error> {
        let mut s = String::new();
        File::open("hello.txt")?.read_to_string(&mut s)?;
        Ok(s)
    }
    ```

    另外需要注意的是，由于每个函数定义的`Err`类型不一定一致，**因此`?`在遇到`Err`需要返回时还会额外将错误传给`From` trait进行错误类型转换**，即`impl From<OtherError> for ReturnedError`

    在返回`Option`的函数调用链中也可以使用`?`进行提前返回，所有返回类型同样必须兼容：

    ```rust
    fn last_char_of_first_line(text: &str) -> Option<char> {
        text.lines().next()?.chars().last()
    }
    ```

## 9.3 To `panic!` or Not to `panic!`

- **实例、原型、测试**
  在这些场合中通常更适合直接`panic!`而不是返回一个`Result`，在编写实例和原型代码时，一个可靠稳健的错误处理逻辑可能会让实例和原型本身难以理解，违背了**快速原型快速展示**的目的（通常这些场合的输入输出是严格控制的，不太可能会出现崩溃），而在测试中如果遇到了预期外的情况直接选择`panic!`让整个测试快速失败（**fail fast**）
- **当有比编译器更多的知识时**
  通常编译器只能依赖代码本身，无法拥有具体场景的知识，因此例如当你确定一个`Result`一定包含了`Ok`的情况时可以很自然使用`.unwrap`并且确信不会出现崩溃
- **错误处理的基本原则**
  在处于**错误状态bad state**时果断`panic!`（违反了前提条件，依赖该状态为正常才能继续执行，不变量被破坏等等），错误状态是预期外的情况而不是预料中的情况，前者例如访问到不允许访问的内存空间，后者例如用户输入的数据格式不正确这种很可能发生的情况，并且对预期外的情况无法很好的将这种情况描述在类型里

  在Rust中由于编译器会确保异常`Result`都得到处理，因此对于常规的类型如`i32`可以认为一定持有一个有效的数据（否则无法通过编译）